Workbook

Sheet Summary
B3: Project | F3: Carillon | S3: Date: | U3: 42998
B4: Location | F4: Lawrenceville, GA | S4: By: | U4: WHM
B5: Description | F5: Millhaven GL | S5: House Faces: | V5: Worst | X5: South
B9: BUILDING DATA | J9: DESIGN CONDITIONS | T9: ENERGY CALCULATIONS
B10: Typical Ceiling Height | G10: 8.5 | H10: ft | L10: Summer | N10: Winter
B11: Floor Area | G11: ='Unit 1 a'!G4+'Unit 1 b'!G4 -> 2512 | H11: ft2 | J11: Outdoor | L11: 95 | M11: °Fdb | N11: 18 | O11: °Fdb
B12: Volume | G12: ='Unit 1 a'!I4+'Unit 1 b'!I4 -> 21928 | H12: ft3 | J12: Indoor | L12: 75 | M12: °Fdb | N12: 72 | O12: °Fdb
B13: Building Tightness | G13: Tight | H13: 0.25 | J13: Delta T | L13: 20 | M13: °Fdb | N13: 54 | O13: °Fdb
J14: Range | L14: 17.3 | M14: °Fdb
B17: Construction Descriptions
B18: Walls / Partitions | D18: # | F18: U-Value | G18: Description / Notes
D19: W1 | F19: 0.077 | G19: Above Grade | L19: 2x4 | P19: R-13 batt
D20: W2 | F20: 0.067 | G20: Basement | L20: Concrete + 2x4 | P20: R-13 batt
D21: W3 | F21: 0.053 | G21: Attic | L21: 2x6 | P21: R19 batt
B22: Doors | D22: # | F22: U-Value | G22: Description / Notes
D23: D1 | F23: 0.5 | G23: Exterior Door | P23: R-2
D24: D2 | F24: 0.5 | G24: Garage Door | P24: R-2
B25: Roofs | D25: # | F25: U-Value | G25: Description / Notes
D26: R1 | F26: 0.026 | G26: Flat Ceiling | L26: Truss | P26: R-38 Blown
D27: R2 | F27: 0.26 | G27: Vaulted | L27: Truss | P27: R-38 Blown
B28: Floors | D28: # | F28: U-Value | G28: Description / Notes
D29: F1 | F29: 0.053 | G29: Framed | L29: I-Joist | P29: R-19 batt
D30: F2 | F30: 0.1 | G30: Slab | P30: None
B31: Glass | D31: # | F31: Glass Type | K31: Windows | N31: U-Value | P31: Internal Shading | V31: Notes
D32: G1 | F32: Double Insulated | K32: All Types | N32: 0.35 | P32: Blinds/ Draperies | V32: SHGC | X32: 0.22
D33: G2
D34: G3
B37: Load Summary
I39: Unit 1 | L39: Unit 2 | Q39: Unit 3
I40: Cooling | J40: Heating | L40: Cooling | N40: Heating | Q40: Cooling | U40: Heating
B41: Sensible Load | H41: btu/hr | I41: ='Unit 1 a'!J54+'Unit 1 b'!J54 -> 24842.335 | J41: ='Unit 1 a'!J77+'Unit 1 b'!J77 -> 30169.222 | L41: ='Unit 2 a'!J54+'Unit 2 b'!J54 -> 0 | N41: ='Unit 2 a'!J77+'Unit 2 b'!J77 -> 0
B42: Minimum Nominal Capacity | H42: tons | I42: ='Unit 1 a'!J55+'Unit 1 b'!J55 -> 2.7602595 | J42: ='Unit 1 a'!J78+'Unit 1 b'!J78 -> 8.8395025 | K42: kW | L42: ='Unit 2 a'!J55+'Unit 2 b'!J55 -> 0 | N42: ='Unit 2 a'!J78+'Unit 2 b'!J78 -> 0 | O42: kW
B43: Load Density | H43: sf/ton | I43: =I44/I42 -> 910.05937 | J43: =J42*1000/G11 -> 3.5189102 | K43: W/sf
B44: Floor Area Served | H44: sf | I44: =G11 -> 2512
B45: System Size | H45: tons | I45: ='Unit 1 a'!E56+'Unit 1 b'!E56 -> 3.5 | J45: ='Unit 1 a'!E79+'Unit 1 b'!E79 -> 10 | K45: kW
B46: Leaving Air Temperature | H46: °f | I46: 57.2 | J46: 96.3
B47: Installed Capacity | H47: sf/ton | I47: =I44/I45 -> 717.71429 | J47: =J45*1000/I44 -> 3.9808917 | K47: w/sf

Sheet Rooms Walls and Glass
A1: Room Name | D1: Entry | E1: Family | F1: PS WIC | G1: PS Bath | H1: PS Bed | I1: Breakfast / Kitchen | J1: Powder | K1: Stairs | L1: Loft | M1: Master Bed | N1: Master Bath | O1: Master WIC | P1: Bed 3 WIC | Q1: Bed 3 | R1: Bath2 | S1: Bed 4 | T1: Hallway | U1: Laundry
A2: Front Faces: | B2: NorthEast | D2: Unit 1 b | E2: Unit 1 b | F2: Unit 1 b | G2: Unit 1 b | H2: Unit 1 b | I2: Unit 1 b | J2: Unit 1 b | K2: Unit 1 a | L2: Unit 1 a | M2: Unit 1 a | N2: Unit 1 a | O2: Unit 1 a | P2: Unit 1 a | Q2: Unit 1 a | R2: Unit 1 a | S2: Unit 1 a | T2: Unit 1 a | U2: Unit 1 a
A3: People | E3: 1 | H3: 1 | L3: 1 | M3: 1 | Q3: 1 | S3: 1
A4: Appliances | E4: 250 | I4: 680 | L4: 250 | U4: 200
A5: Glass & Doors | D5: Glass & Doors
A7: Direction | B7: Facing | C7: Type | D7: =D1 -> Entry | E7: =E1 -> Family | F7: =F1 -> PS WIC | G7: =G1 -> PS Bath | H7: =H1 -> PS Bed | I7: =I1 -> Breakfast / Kitchen | J7: =J1 -> Powder | K7: =K1 -> Stairs | ... AB7: =AB1 -> 0
A8: =IF(A15="North","Northeast",IF(A15="NorthEast","East",IF(A15="East","SouthEast",IF(A15="SouthEast","South",IF(A15="South","SouthWest",IF(A15="SouthWest","West",IF(A15="West","NorthWest","North"))))))) -> NorthWest | B8: Right | C8: G1 | E8: 36 | L8: 30
A9: =IF(A8="North","Northeast",IF(A8="NorthEast","East",IF(A8="East","SouthEast",IF(A8="SouthEast","South",IF(A8="South","SouthWest",IF(A8="SouthWest","West",IF(A8="West","NorthWest","North"))))))) -> North | C9: G1
A10: =$B$2 -> NorthEast | B10: Front | C10: G1 | K10: 8 | M10: 38
A11: =IF(A10="North","Northeast",IF(A10="NorthEast","East",IF(A10="East","SouthEast",IF(A10="SouthEast","South",IF(A10="South","SouthWest",IF(A10="SouthWest","West",IF(A10="West","NorthWest","North"))))))) -> East | C11: G1
A12: =IF(A11="North","Northeast",IF(A11="NorthEast","East",IF(A11="East","SouthEast",IF(A11="SouthEast","South",IF(A11="South","SouthWest",IF(A11="SouthWest","West",IF(A11="West","NorthWest","North"))))))) -> SouthEast | B12: Left | C12: G1 | G12: 3 | N12: 16
A13: =IF(A12="North","Northeast",IF(A12="NorthEast","East",IF(A12="East","SouthEast",IF(A12="SouthEast","South",IF(A12="South","SouthWest",IF(A12="SouthWest","West",IF(A12="West","NorthWest","North"))))))) -> South | C13: G1
A14: =IF(A13="North","Northeast",IF(A13="NorthEast","East",IF(A13="East","SouthEast",IF(A13="SouthEast","South",IF(A13="South","SouthWest",IF(A13="SouthWest","West",IF(A13="West","NorthWest","North"))))))) -> SouthWest | B14: Back | C14: G1 | H14: 36 | I14: 45 | Q14: 15 | S14: 15
A15: =IF(A14="North","Northeast",IF(A14="NorthEast","East",IF(A14="East","SouthEast",IF(A14="SouthEast","South",IF(A14="South","SouthWest",IF(A14="SouthWest","West",IF(A14="West","NorthWest","North"))))))) -> West | C15: G1
A16: Sky Light | C16: G1
A17: Shaded | C17: G1 | D17: 6
A18: Door 1 | C18: D1 | D18: 16.7 | I18: 8
A19: Door 2 | C19: D2 | D19: 17.8
A20: Above Grade Walls | D20: Above Grade Walls
A22: Direction | B22: Facing | C22: Type | D22: =D1 -> Entry | E22: =E1 -> Family | F22: =F1 -> PS WIC | G22: =G1 -> PS Bath | H22: =H1 -> PS Bed | I22: =I1 -> Breakfast / Kitchen | J22: =J1 -> Powder | K22: =K1 -> Stairs | ... AB22: =AB1 -> 0
A23: =IF(A30="North","Northeast",IF(A30="NorthEast","East",IF(A30="East","SouthEast",IF(A30="SouthEast","South",IF(A30="South","SouthWest",IF(A30="SouthWest","West",IF(A30="West","NorthWest","North"))))))) -> NorthWest | B23: Right | C23: W1 | D23: 99 | E23: 94 | I23: 138 | J23: 48 | K23: 130 | L23: 85 | S23: 122
A24: =IF(A23="North","Northeast",IF(A23="NorthEast","East",IF(A23="East","SouthEast",IF(A23="SouthEast","South",IF(A23="South","SouthWest",IF(A23="SouthWest","West",IF(A23="West","NorthWest","North"))))))) -> North | C24: W1
A25: =$B$2 -> NorthEast | B25: Front | C25: W1 | D25: 84 | K25: 72 | M25: 122
A26: =IF(A25="North","Northeast",IF(A25="NorthEast","East",IF(A25="East","SouthEast",IF(A25="SouthEast","South",IF(A25="South","SouthWest",IF(A25="SouthWest","West",IF(A25="West","NorthWest","North"))))))) -> East | C26: W1
A27: =IF(A26="North","Northeast",IF(A26="NorthEast","East",IF(A26="East","SouthEast",IF(A26="SouthEast","South",IF(A26="South","SouthWest",IF(A26="SouthWest","West",IF(A26="West","NorthWest","North"))))))) -> SouthEast | B27: Left | C27: W1 | F27: 50 | G27: 78 | H27: 138 | M27: 138 | N27: 60 | O27: 62 | P27: 29 | Q27: 94
A28: =IF(A27="North","Northeast",IF(A27="NorthEast","East",IF(A27="East","SouthEast",IF(A27="SouthEast","South",IF(A27="South","SouthWest",IF(A27="SouthWest","West",IF(A27="West","NorthWest","North"))))))) -> South | C28: W1
A29: =IF(A28="North","Northeast",IF(A28="NorthEast","East",IF(A28="East","SouthEast",IF(A28="SouthEast","South",IF(A28="South","SouthWest",IF(A28="SouthWest","West",IF(A28="West","NorthWest","North"))))))) -> SouthWest | B29: Back | C29: W1 | H29: 99 | I29: 90 | Q29: 94 | R29: 42 | S29: 73
A30: =IF(A29="North","Northeast",IF(A29="NorthEast","East",IF(A29="East","SouthEast",IF(A29="SouthEast","South",IF(A29="South","SouthWest",IF(A29="SouthWest","West",IF(A29="West","NorthWest","North"))))))) -> West | C30: W1
A31: Exterior Perimeter | D31: =IF((SUM(D23:D30)+SUM(D18:D19))=0,"-",(SUM(D23:D30)+SUM(D18:D19))/Summary!$G$10) -> 25.588235 | E31: =IF((SUM(E23:E30)+SUM(E18:E19))=0,"-",(SUM(E23:E30)+SUM(E18:E19))/Summary!$G$10) -> 11.058824 | F31: =IF((SUM(F23:F30)+SUM(F18:F19))=0,"-",(SUM(F23:F30)+SUM(F18:F19))/Summary!$G$10) -> 5.8823529 | G31: =IF((SUM(G23:G30)+SUM(G18:G19))=0,"-",(SUM(G23:G30)+SUM(G18:G19))/Summary!$G$10) -> 9.1764706 | H31: =IF((SUM(H23:H30)+SUM(H18:H19))=0,"-",(SUM(H23:H30)+SUM(H18:H19))/Summary!$G$10) -> 27.882353 | I31: =IF((SUM(I23:I30)+SUM(I18:I19))=0,"-",(SUM(I23:I30)+SUM(I18:I19))/Summary!$G$10) -> 27.764706 | J31: =IF((SUM(J23:J30)+SUM(J18:J19))=0,"-",(SUM(J23:J30)+SUM(J18:J19))/Summary!$G$10) -> 5.6470588 | K31: =IF((SUM(K23:K30)+SUM(K18:K19))=0,"-",(SUM(K23:K30)+SUM(K18:K19))/Summary!$G$10) -> 23.764706 | ... AB31: =IF((SUM(AB23:AB30)+SUM(AB18:AB19))=0,"-",(SUM(AB23:AB30)+SUM(AB18:AB19))/Summary!$G$10) -> -
A32: Basement Walls
A34: Direction | B34: Facing | C34: Type | D34: =D1 -> Entry | E34: =E1 -> Family | F34: =F1 -> PS WIC | G34: =G1 -> PS Bath | H34: =H1 -> PS Bed | I34: =I1 -> Breakfast / Kitchen | J34: =J1 -> Powder | K34: =K1 -> Stairs | ... AB34: =AB1 -> 0
A35: =IF(A42="North","Northeast",IF(A42="NorthEast","East",IF(A42="East","SouthEast",IF(A42="SouthEast","South",IF(A42="South","SouthWest",IF(A42="SouthWest","West",IF(A42="West","NorthWest","North"))))))) -> NorthWest | B35: Right | C35: W1
A36: =IF(A35="North","Northeast",IF(A35="NorthEast","East",IF(A35="East","SouthEast",IF(A35="SouthEast","South",IF(A35="South","SouthWest",IF(A35="SouthWest","West",IF(A35="West","NorthWest","North"))))))) -> North | C36: W1
A37: =$B$2 -> NorthEast | B37: Front | C37: W1
A38: =IF(A37="North","Northeast",IF(A37="NorthEast","East",IF(A37="East","SouthEast",IF(A37="SouthEast","South",IF(A37="South","SouthWest",IF(A37="SouthWest","West",IF(A37="West","NorthWest","North"))))))) -> East | C38: W1
A39: =IF(A38="North","Northeast",IF(A38="NorthEast","East",IF(A38="East","SouthEast",IF(A38="SouthEast","South",IF(A38="South","SouthWest",IF(A38="SouthWest","West",IF(A38="West","NorthWest","North"))))))) -> SouthEast | B39: Left | C39: W1
A40: =IF(A39="North","Northeast",IF(A39="NorthEast","East",IF(A39="East","SouthEast",IF(A39="SouthEast","South",IF(A39="South","SouthWest",IF(A39="SouthWest","West",IF(A39="West","NorthWest","North"))))))) -> South | C40: W1
A41: =IF(A40="North","Northeast",IF(A40="NorthEast","East",IF(A40="East","SouthEast",IF(A40="SouthEast","South",IF(A40="South","SouthWest",IF(A40="SouthWest","West",IF(A40="West","NorthWest","North"))))))) -> SouthWest | B41: Back | C41: W1
A42: =IF(A41="North","Northeast",IF(A41="NorthEast","East",IF(A41="East","SouthEast",IF(A41="SouthEast","South",IF(A41="South","SouthWest",IF(A41="SouthWest","West",IF(A41="West","NorthWest","North"))))))) -> West | C42: W1
A43: Exterior Perimeter | D43: =IF((SUM(D35:D42)+SUM(D18:D19))=0,"-",(SUM(D35:D42)+SUM(D18:D19))/Summary!$G$10) -> 4.0588235 | E43: =IF((SUM(E35:E42)+SUM(E18:E19))=0,"-",(SUM(E35:E42)+SUM(E18:E19))/Summary!$G$10) -> - | F43: =IF((SUM(F35:F42)+SUM(F18:F19))=0,"-",(SUM(F35:F42)+SUM(F18:F19))/Summary!$G$10) -> - | G43: =IF((SUM(G35:G42)+SUM(G18:G19))=0,"-",(SUM(G35:G42)+SUM(G18:G19))/Summary!$G$10) -> - | H43: =IF((SUM(H35:H42)+SUM(H18:H19))=0,"-",(SUM(H35:H42)+SUM(H18:H19))/Summary!$G$10) -> - | I43: =IF((SUM(I35:I42)+SUM(I18:I19))=0,"-",(SUM(I35:I42)+SUM(I18:I19))/Summary!$G$10) -> 0.94117647 | J43: =IF((SUM(J35:J42)+SUM(J18:J19))=0,"-",(SUM(J35:J42)+SUM(J18:J19))/Summary!$G$10) -> - | K43: =IF((SUM(K35:K42)+SUM(K18:K19))=0,"-",(SUM(K35:K42)+SUM(K18:K19))/Summary!$G$10) -> - | ... AB43: =IF((SUM(AB35:AB42)+SUM(AB18:AB19))=0,"-",(SUM(AB35:AB42)+SUM(AB18:AB19))/Summary!$G$10) -> -
...

Sheet Unit 1 a
B1: Project | E1: =Summary!F3 -> Carillon | M1: Date: | N1: 42998 | T1: Typical Ceiling Height | W1: =Summary!G10 -> 8.5
B2: Location | E2: =Summary!F4 -> Lawrenceville, GA | M2: By:
B3: Description | E3: =Summary!F5 -> Millhaven GL | M3: Level(s): | N3: First Floor | Q3: Unit 1 a | T3: Kneewall Height | W3: 1
E4: Square Feet | G4: =SUM(I42:I43) -> 1474 | H4: Volume | I4: =I50 -> 13105 | J4: Sf/Ton | K4: =G4/E56 -> 842.28571 | M4: SEER | N4: 14
I6: Ceiling Height | K6: =$W$1 -> 8.5 | M6: =$W$1 -> 8.5 | O6: =$W$1 -> 8.5 | Q6: =$W$1 -> 8.5 | S6: =$W$1 -> 8.5 | U6: =$W$1 -> 8.5 | W6: 12 | Y6: =$W$1 -> 8.5 | AA6: =$W$1 -> 8.5 | AC6: =$W$1 -> 8.5 | AE6: 9 | AG6: =$W$1 -> 8.5 | AI6: =$W$1 -> 8.5 | AK6: 8 | AM6: 8 | AO6: 8
B7: Components | E7: CLTD (°F) | F7: U-Value (Btu/hr-sf-°F) | G7: Cooling Load Factor | I7: Entire House | K7: {=IFERROR(INDEX('Rooms Walls and Glass'!$D$7:$AB$7,MATCH(0,IF('Unit 1 a'!$Q$3='Rooms Walls and Glass'!$D$2:$AB$2,COUNTIF($E$1:$E1,'Rooms Walls and Glass'!E7:AB$7),""),0)),"")} -> Stairs | M7: {=IFERROR(INDEX('Rooms Walls and Glass'!$D$7:$AB$7,MATCH(0,IF('Unit 1 a'!$Q$3='Rooms Walls and Glass'!$D$2:$AB$2,COUNTIF(K7,'Rooms Walls and Glass'!D$7:$AB$7),""),0)),"")} -> Loft | O7: {=IFERROR(INDEX('Rooms Walls and Glass'!$D$7:$AB$7,MATCH(0,IF('Unit 1 a'!$Q$3='Rooms Walls and Glass'!$D$2:$AB$2,COUNTIF(K7:M7,'Rooms Walls and Glass'!D$7:$AB$7),""),0)),"")} -> Master Bed | Q7: {=IFERROR(INDEX('Rooms Walls and Glass'!$D$7:$AB$7,MATCH(0,IF('Unit 1 a'!$Q$3='Rooms Walls and Glass'!$D$2:$AB$2,COUNTIF($K$7:O$7,'Rooms Walls and Glass'!D$7:$AB$7),""),0)),"")} -> Master Bath | S7: {=IFERROR(INDEX('Rooms Walls and Glass'!$D$7:$AB$7,MATCH(0,IF('Unit 1 a'!$Q$3='Rooms Walls and Glass'!$D$2:$AB$2,COUNTIF($K$7:R$7,'Rooms Walls and Glass'!$D$7:$AB$7),""),0)),"")} -> Master WIC | U7: {=IFERROR(INDEX('Rooms Walls and Glass'!$D$7:$AB$7,MATCH(0,IF('Unit 1 a'!$Q$3='Rooms Walls and Glass'!$D$2:$AB$2,COUNTIF($K$7:T$7,'Rooms Walls and Glass'!$D$7:$AB$7),""),0)),"")} -> Bed 3 WIC | W7: {=IFERROR(INDEX('Rooms Walls and Glass'!$D$7:$AB$7,MATCH(0,IF('Unit 1 a'!$Q$3='Rooms Walls and Glass'!$D$2:$AB$2,COUNTIF($K$7:V$7,'Rooms Walls and Glass'!$D$7:$AB$7),""),0)),"")} -> Bed 3 | Y7: {=IFERROR(INDEX('Rooms Walls and Glass'!$D$7:$AB$7,MATCH(0,IF('Unit 1 a'!$Q$3='Rooms Walls and Glass'!$D$2:$AB$2,COUNTIF($K$7:X$7,'Rooms Walls and Glass'!$D$7:$AB$7),""),0)),"")} -> Bath2 | AA7: {=IFERROR(INDEX('Rooms Walls and Glass'!$D$7:$AB$7,MATCH(0,IF('Unit 1 a'!$Q$3='Rooms Walls and Glass'!$D$2:$AB$2,COUNTIF($K$7:Z$7,'Rooms Walls and Glass'!$D$7:$AB$7),""),0)),"")} -> Bed 4 | AC7: {=IFERROR(INDEX('Rooms Walls and Glass'!$D$7:$AB$7,MATCH(0,IF('Unit 1 a'!$Q$3='Rooms Walls and Glass'!$D$2:$AB$2,COUNTIF($K$7:AB$7,'Rooms Walls and Glass'!$D$7:$AB$7),""),0)),"")} -> Hallway | AE7: {=IFERROR(INDEX('Rooms Walls and Glass'!$D$7:$AB$7,MATCH(0,IF('Unit 1 a'!$Q$3='Rooms Walls and Glass'!$D$2:$AB$2,COUNTIF($K$7:AD$7,'Rooms Walls and Glass'!$D$7:$AB$7),""),0)),"")} -> Laundry | AG7: {=IFERROR(INDEX('Rooms Walls and Glass'!$D$7:$AB$7,MATCH(0,IF('Unit 1 a'!$Q$3='Rooms Walls and Glass'!$D$2:$AB$2,COUNTIF($K$7:AF$7,'Rooms Walls and Glass'!$D$7:$AB$7),""),0)),"")} | AI7: {=IFERROR(INDEX('Rooms Walls and Glass'!$D$7:$AB$7,MATCH(0,IF('Unit 1 a'!$Q$3='Rooms Walls and Glass'!$D$2:$AB$2,COUNTIF($K$7:AH$7,'Rooms Walls and Glass'!$D$7:$AB$7),""),0)),"")} | AK7: {=IFERROR(INDEX('Rooms Walls and Glass'!$D$7:$AB$7,MATCH(0,IF('Unit 1 a'!$Q$3='Rooms Walls and Glass'!$D$2:$AB$2,COUNTIF($K$7:AJ$7,'Rooms Walls and Glass'!$D$7:$AB$7),""),0)),"")} | AM7: {=IFERROR(INDEX('Rooms Walls and Glass'!$D$7:$AB$7,MATCH(0,IF('Unit 1 a'!$Q$3='Rooms Walls and Glass'!$D$2:$AB$2,COUNTIF($K$7:AK$7,'Rooms Walls and Glass'!$D$7:$AB$7),""),0)),"")} | AO7: {=IFERROR(INDEX('Rooms Walls and Glass'!$D$7:$AB$7,MATCH(0,IF('Unit 1 a'!$Q$3='Rooms Walls and Glass'!$D$2:$AB$2,COUNTIF($K$7:AN$7,'Rooms Walls and Glass'!$D$7:$AB$7),""),0)),"")}
C8: Type | D8: Description | I8: Qty | J8: Btu/hr | K8: Qty | L8: Btu/hr | M8: Qty | N8: Btu/hr | O8: Qty | P8: Btu/hr | Q8: Qty | R8: Btu/hr | S8: Qty | T8: Btu/hr | U8: Qty | V8: Btu/hr | W8: Qty | X8: Btu/hr | Y8: Qty | Z8: Btu/hr | AA8: Qty | AB8: Btu/hr | AC8: Qty | AD8: Btu/hr | AE8: Qty | AF8: Btu/hr | AG8: Qty | AH8: Btu/hr | AI8: Qty | AJ8: Btu/hr | AK8: Qty | AL8: Btu/hr | AM8: Qty | AN8: Btu/hr | AO8: Qty | AP8: Btu/hr
B9: Glass | C9: G1 | D9: ='Rooms Walls and Glass'!A8 -> NorthWest | E9: Right | F9: (E) | G9: =INDEX('Glass CLF Calculation'!$A$4:$G$11,MATCH('Unit 1 a'!D9,'Glass CLF Calculation'!$A$4:$A$11,0),7) -> 18.306649 | H9: Btu/hr-sf | I9: =SUM(K9,M9,O9,Q9,U9,W9,Y9,AA9,AC9,AE9,AG9,AI9,S9,AK9,AM9,AO9) -> 30 | J9: =IF(I9="","-",I9*$G9) -> 549.19947 | K9: =IF(K$7="","",IF(INDEX('Rooms Walls and Glass'!$D$3:$AB$17, MATCH($D9,'Rooms Walls and Glass'!$A$3:$A$17,0), MATCH('Unit 1 a'!K$7,'Rooms Walls and Glass'!$D$1:$AB$1,0))=0,"",INDEX('Rooms Walls and Glass'!$D$3:$AB$17, MATCH($D9,'Rooms Walls and Glass'!$A$3:$A$17,0), MATCH('Unit 1 a'!K$7,'Rooms Walls and Glass'!$D$1:$AB$1,0)))) | L9: =IF(K9="","-",K9*$G9) -> - | M9: =IF(M$7="","",IF(INDEX('Rooms Walls and Glass'!$D$3:$AB$17, MATCH($D9,'Rooms Walls and Glass'!$A$3:$A$17,0), MATCH('Unit 1 a'!M$7,'Rooms Walls and Glass'!$D$1:$AB$1,0))=0,"",INDEX('Rooms Walls and Glass'!$D$3:$AB$17, MATCH($D9,'Rooms Walls and Glass'!$A$3:$A$17,0), MATCH('Unit 1 a'!M$7,'Rooms Walls and Glass'!$D$1:$AB$1,0)))) -> 30 | N9: =IF(M9="","-",M9*$G9) -> 549.19947 | O9: =IF(O$7="","",IF(INDEX('Rooms Walls and Glass'!$D$3:$AB$17, MATCH($D9,'Rooms Walls and Glass'!$A$3:$A$17,0), MATCH('Unit 1 a'!O$7,'Rooms Walls and Glass'!$D$1:$AB$1,0))=0,"",INDEX('Rooms Walls and Glass'!$D$3:$AB$17, MATCH($D9,'Rooms Walls and Glass'!$A$3:$A$17,0), MATCH('Unit 1 a'!O$7,'Rooms Walls and Glass'!$D$1:$AB$1,0)))) | P9: =IF(O9="","-",O9*$G9) -> - | Q9: =IF(Q$7="","",IF(INDEX('Rooms Walls and Glass'!$D$3:$AB$17, MATCH($D9,'Rooms Walls and Glass'!$A$3:$A$17,0), MATCH('Unit 1 a'!Q$7,'Rooms Walls and Glass'!$D$1:$AB$1,0))=0,"",INDEX('Rooms Walls and Glass'!$D$3:$AB$17, MATCH($D9,'Rooms Walls and Glass'!$A$3:$A$17,0), MATCH('Unit 1 a'!Q$7,'Rooms Walls and Glass'!$D$1:$AB$1,0)))) | R9: =IF(Q9="","-",Q9*$G9) -> - | S9: =IF(S$7="","",IF(INDEX('Rooms Walls and Glass'!$D$3:$AB$17, MATCH($D9,'Rooms Walls and Glass'!$A$3:$A$17,0), MATCH('Unit 1 a'!S$7,'Rooms Walls and Glass'!$D$1:$AB$1,0))=0,"",INDEX('Rooms Walls and Glass'!$D$3:$AB$17, MATCH($D9,'Rooms Walls and Glass'!$A$3:$A$17,0), MATCH('Unit 1 a'!S$7,'Rooms Walls and Glass'!$D$1:$AB$1,0)))) | T9: =IF(S9="","-",S9*$G9) -> - | U9: =IF(U$7="","",IF(INDEX('Rooms Walls and Glass'!$D$3:$AB$17, MATCH($D9,'Rooms Walls and Glass'!$A$3:$A$17,0), MATCH('Unit 1 a'!U$7,'Rooms Walls and Glass'!$D$1:$AB$1,0))=0,"",INDEX('Rooms Walls and Glass'!$D$3:$AB$17, MATCH($D9,'Rooms Walls and Glass'!$A$3:$A$17,0), MATCH('Unit 1 a'!U$7,'Rooms Walls and Glass'!$D$1:$AB$1,0)))) | V9: =IF(U9="","-",U9*$G9) -> - | W9: =IF(W$7="","",IF(INDEX('Rooms Walls and Glass'!$D$3:$AB$17, MATCH($D9,'Rooms Walls and Glass'!$A$3:$A$17,0), MATCH('Unit 1 a'!W$7,'Rooms Walls and Glass'!$D$1:$AB$1,0))=0,"",INDEX('Rooms Walls and Glass'!$D$3:$AB$17, MATCH($D9,'Rooms Walls and Glass'!$A$3:$A$17,0), MATCH('Unit 1 a'!W$7,'Rooms Walls and Glass'!$D$1:$AB$1,0)))) | X9: =IF(W9="","-",W9*$G9) -> - | Y9: =IF(Y$7="","",IF(INDEX('Rooms Walls and Glass'!$D$3:$AB$17, MATCH($D9,'Rooms Walls and Glass'!$A$3:$A$17,0), MATCH('Unit 1 a'!Y$7,'Rooms Walls and Glass'!$D$1:$AB$1,0))=0,"",INDEX('Rooms Walls and Glass'!$D$3:$AB$17, MATCH($D9,'Rooms Walls and Glass'!$A$3:$A$17,0), MATCH('Unit 1 a'!Y$7,'Rooms Walls and Glass'!$D$1:$AB$1,0)))) | Z9: =IF(Y9="","-",Y9*$G9) -> - | AA9: =IF(AA$7="","",IF(INDEX('Rooms Walls and Glass'!$D$3:$AB$17, MATCH($D9,'Rooms Walls and Glass'!$A$3:$A$17,0), MATCH('Unit 1 a'!AA$7,'Rooms Walls and Glass'!$D$1:$AB$1,0))=0,"",INDEX('Rooms Walls and Glass'!$D$3:$AB$17, MATCH($D9,'Rooms Walls and Glass'!$A$3:$A$17,0), MATCH('Unit 1 a'!AA$7,'Rooms Walls and Glass'!$D$1:$AB$1,0)))) | AB9: =IF(AA9="","-",AA9*$G9) -> - | AC9: =IF(AC$7="","",IF(INDEX('Rooms Walls and Glass'!$D$3:$AB$17, MATCH($D9,'Rooms Walls and Glass'!$A$3:$A$17,0), MATCH('Unit 1 a'!AC$7,'Rooms Walls and Glass'!$D$1:$AB$1,0))=0,"",INDEX('Rooms Walls and Glass'!$D$3:$AB$17, MATCH($D9,'Rooms Walls and Glass'!$A$3:$A$17,0), MATCH('Unit 1 a'!AC$7,'Rooms Walls and Glass'!$D$1:$AB$1,0)))) | AD9: =IF(AC9="","-",AC9*$G9) -> - | AE9: =IF(AE$7="","",IF(INDEX('Rooms Walls and Glass'!$D$3:$AB$17, MATCH($D9,'Rooms Walls and Glass'!$A$3:$A$17,0), MATCH('Unit 1 a'!AE$7,'Rooms Walls and Glass'!$D$1:$AB$1,0))=0,"",INDEX('Rooms Walls and Glass'!$D$3:$AB$17, MATCH($D9,'Rooms Walls and Glass'!$A$3:$A$17,0), MATCH('Unit 1 a'!AE$7,'Rooms Walls and Glass'!$D$1:$AB$1,0)))) | AF9: =IF(AE9="","-",AE9*$G9) -> - | AG9: =IF(AG$7="","",IF(INDEX('Rooms Walls and Glass'!$D$3:$AB$17, MATCH($D9,'Rooms Walls and Glass'!$A$3:$A$17,0), MATCH('Unit 1 a'!AG$7,'Rooms Walls and Glass'!$D$1:$AB$1,0))=0,"",INDEX('Rooms Walls and Glass'!$D$3:$AB$17, MATCH($D9,'Rooms Walls and Glass'!$A$3:$A$17,0), MATCH('Unit 1 a'!AG$7,'Rooms Walls and Glass'!$D$1:$AB$1,0)))) | AH9: =IF(AG9="","-",AG9*$G9) -> - | AI9: =IF(AI$7="","",IF(INDEX('Rooms Walls and Glass'!$D$3:$AB$17, MATCH($D9,'Rooms Walls and Glass'!$A$3:$A$17,0), MATCH('Unit 1 a'!AI$7,'Rooms Walls and Glass'!$D$1:$AB$1,0))=0,"",INDEX('Rooms Walls and Glass'!$D$3:$AB$17, MATCH($D9,'Rooms Walls and Glass'!$A$3:$A$17,0), MATCH('Unit 1 a'!AI$7,'Rooms Walls and Glass'!$D$1:$AB$1,0)))) | AJ9: =IF(AI9="","-",AI9*$G9) -> - | AK9: =IF(AK$7="","",IF(INDEX('Rooms Walls and Glass'!$D$3:$AB$17, MATCH($D9,'Rooms Walls and Glass'!$A$3:$A$17,0), MATCH('Unit 1 a'!AK$7,'Rooms Walls and Glass'!$D$1:$AB$1,0))=0,"",INDEX('Rooms Walls and Glass'!$D$3:$AB$17, MATCH($D9,'Rooms Walls and Glass'!$A$3:$A$17,0), MATCH('Unit 1 a'!AK$7,'Rooms Walls and Glass'!$D$1:$AB$1,0)))) | AL9: =IF(AK9="","-",AK9*$G9) -> - | AM9: =IF(AM$7="","",IF(INDEX('Rooms Walls and Glass'!$D$3:$AB$17, MATCH($D9,'Rooms Walls and Glass'!$A$3:$A$17,0), MATCH('Unit 1 a'!AM$7,'Rooms Walls and Glass'!$D$1:$AB$1,0))=0,"",INDEX('Rooms Walls and Glass'!$D$3:$AB$17, MATCH($D9,'Rooms Walls and Glass'!$A$3:$A$17,0), MATCH('Unit 1 a'!AM$7,'Rooms Walls and Glass'!$D$1:$AB$1,0)))) | AN9: =IF(AM9="","-",AM9*$G9) -> - | AO9: =IF(AO$7="","",IF(INDEX('Rooms Walls and Glass'!$D$3:$AB$17, MATCH($D9,'Rooms Walls and Glass'!$A$3:$A$17,0), MATCH('Unit 1 a'!AO$7,'Rooms Walls and Glass'!$D$1:$AB$1,0))=0,"",INDEX('Rooms Walls and Glass'!$D$3:$AB$17, MATCH($D9,'Rooms Walls and Glass'!$A$3:$A$17,0), MATCH('Unit 1 a'!AO$7,'Rooms Walls and Glass'!$D$1:$AB$1,0)))) | AP9: =IF(AO9="","-",AO9*$G9) -> -
C10: G1 | D10: ='Rooms Walls and Glass'!A9 -> North | F10: (SE) | G10: =INDEX('Glass CLF Calculation'!$A$4:$G$11,MATCH('Unit 1 a'!D10,'Glass CLF Calculation'!$A$4:$A$11,0),7) -> 6.2012662 | H10: Btu/hr-sf | I10: =SUM(K10,M10,O10,Q10,U10,W10,Y10,AA10,AC10,AE10,AG10,AI10,S10,AK10,AM10,AO10) -> 0 | J10: =IF(I10="","-",I10*$G10) -> 0 | K10: =IF(K$7="","",IF(INDEX('Rooms Walls and Glass'!$D$3:$AB$17, MATCH($D10,'Rooms Walls and Glass'!$A$3:$A$17,0), MATCH('Unit 1 a'!K$7,'Rooms Walls and Glass'!$D$1:$AB$1,0))=0,"",INDEX('Rooms Walls and Glass'!$D$3:$AB$17, MATCH($D10,'Rooms Walls and Glass'!$A$3:$A$17,0), MATCH('Unit 1 a'!K$7,'Rooms Walls and Glass'!$D$1:$AB$1,0)))) | L10: =IF(K10="","-",K10*$G10) -> - | M10: =IF(M$7="","",IF(INDEX('Rooms Walls and Glass'!$D$3:$AB$17, MATCH($D10,'Rooms Walls and Glass'!$A$3:$A$17,0), MATCH('Unit 1 a'!M$7,'Rooms Walls and Glass'!$D$1:$AB$1,0))=0,"",INDEX('Rooms Walls and Glass'!$D$3:$AB$17, MATCH($D10,'Rooms Walls and Glass'!$A$3:$A$17,0), MATCH('Unit 1 a'!M$7,'Rooms Walls and Glass'!$D$1:$AB$1,0)))) | N10: =IF(M10="","-",M10*$G10) -> - | O10: =IF(O$7="","",IF(INDEX('Rooms Walls and Glass'!$D$3:$AB$17, MATCH($D10,'Rooms Walls and Glass'!$A$3:$A$17,0), MATCH('Unit 1 a'!O$7,'Rooms Walls and Glass'!$D$1:$AB$1,0))=0,"",INDEX('Rooms Walls and Glass'!$D$3:$AB$17, MATCH($D10,'Rooms Walls and Glass'!$A$3:$A$17,0), MATCH('Unit 1 a'!O$7,'Rooms Walls and Glass'!$D$1:$AB$1,0)))) | P10: =IF(O10="","-",O10*$G10) -> - | Q10: =IF(Q$7="","",IF(INDEX('Rooms Walls and Glass'!$D$3:$AB$17, MATCH($D10,'Rooms Walls and Glass'!$A$3:$A$17,0), MATCH('Unit 1 a'!Q$7,'Rooms Walls and Glass'!$D$1:$AB$1,0))=0,"",INDEX('Rooms Walls and Glass'!$D$3:$AB$17, MATCH($D10,'Rooms Walls and Glass'!$A$3:$A$17,0), MATCH('Unit 1 a'!Q$7,'Rooms Walls and Glass'!$D$1:$AB$1,0)))) | R10: =IF(Q10="","-",Q10*$G10) -> - | S10: =IF(S$7="","",IF(INDEX('Rooms Walls and Glass'!$D$3:$AB$17, MATCH($D10,'Rooms Walls and Glass'!$A$3:$A$17,0), MATCH('Unit 1 a'!S$7,'Rooms Walls and Glass'!$D$1:$AB$1,0))=0,"",INDEX('Rooms Walls and Glass'!$D$3:$AB$17, MATCH($D10,'Rooms Walls and Glass'!$A$3:$A$17,0), MATCH('Unit 1 a'!S$7,'Rooms Walls and Glass'!$D$1:$AB$1,0)))) | T10: =IF(S10="","-",S10*$G10) -> - | U10: =IF(U$7="","",IF(INDEX('Rooms Walls and Glass'!$D$3:$AB$17, MATCH($D10,'Rooms Walls and Glass'!$A$3:$A$17,0), MATCH('Unit 1 a'!U$7,'Rooms Walls and Glass'!$D$1:$AB$1,0))=0,"",INDEX('Rooms Walls and Glass'!$D$3:$AB$17, MATCH($D10,'Rooms Walls and Glass'!$A$3:$A$17,0), MATCH('Unit 1 a'!U$7,'Rooms Walls and Glass'!$D$1:$AB$1,0)))) | V10: =IF(U10="","-",U10*$G10) -> - | W10: =IF(W$7="","",IF(INDEX('Rooms Walls and Glass'!$D$3:$AB$17, MATCH($D10,'Rooms Walls and Glass'!$A$3:$A$17,0), MATCH('Unit 1 a'!W$7,'Rooms Walls and Glass'!$D$1:$AB$1,0))=0,"",INDEX('Rooms Walls and Glass'!$D$3:$AB$17, MATCH($D10,'Rooms Walls and Glass'!$A$3:$A$17,0), MATCH('Unit 1 a'!W$7,'Rooms Walls and Glass'!$D$1:$AB$1,0)))) | X10: =IF(W10="","-",W10*$G10) -> - | Y10: =IF(Y$7="","",IF(INDEX('Rooms Walls and Glass'!$D$3:$AB$17, MATCH($D10,'Rooms Walls and Glass'!$A$3:$A$17,0), MATCH('Unit 1 a'!Y$7,'Rooms Walls and Glass'!$D$1:$AB$1,0))=0,"",INDEX('Rooms Walls and Glass'!$D$3:$AB$17, MATCH($D10,'Rooms Walls and Glass'!$A$3:$A$17,0), MATCH('Unit 1 a'!Y$7,'Rooms Walls and Glass'!$D$1:$AB$1,0)))) | Z10: =IF(Y10="","-",Y10*$G10) -> - | AA10: =IF(AA$7="","",IF(INDEX('Rooms Walls and Glass'!$D$3:$AB$17, MATCH($D10,'Rooms Walls and Glass'!$A$3:$A$17,0), MATCH('Unit 1 a'!AA$7,'Rooms Walls and Glass'!$D$1:$AB$1,0))=0,"",INDEX('Rooms Walls and Glass'!$D$3:$AB$17, MATCH($D10,'Rooms Walls and Glass'!$A$3:$A$17,0), MATCH('Unit 1 a'!AA$7,'Rooms Walls and Glass'!$D$1:$AB$1,0)))) | AB10: =IF(AA10="","-",AA10*$G10) -> - | AC10: =IF(AC$7="","",IF(INDEX('Rooms Walls and Glass'!$D$3:$AB$17, MATCH($D10,'Rooms Walls and Glass'!$A$3:$A$17,0), MATCH('Unit 1 a'!AC$7,'Rooms Walls and Glass'!$D$1:$AB$1,0))=0,"",INDEX('Rooms Walls and Glass'!$D$3:$AB$17, MATCH($D10,'Rooms Walls and Glass'!$A$3:$A$17,0), MATCH('Unit 1 a'!AC$7,'Rooms Walls and Glass'!$D$1:$AB$1,0)))) | AD10: =IF(AC10="","-",AC10*$G10) -> - | AE10: =IF(AE$7="","",IF(INDEX('Rooms Walls and Glass'!$D$3:$AB$17, MATCH($D10,'Rooms Walls and Glass'!$A$3:$A$17,0), MATCH('Unit 1 a'!AE$7,'Rooms Walls and Glass'!$D$1:$AB$1,0))=0,"",INDEX('Rooms Walls and Glass'!$D$3:$AB$17, MATCH($D10,'Rooms Walls and Glass'!$A$3:$A$17,0), MATCH('Unit 1 a'!AE$7,'Rooms Walls and Glass'!$D$1:$AB$1,0)))) | AF10: =IF(AE10="","-",AE10*$G10) -> - | AG10: =IF(AG$7="","",IF(INDEX('Rooms Walls and Glass'!$D$3:$AB$17, MATCH($D10,'Rooms Walls and Glass'!$A$3:$A$17,0), MATCH('Unit 1 a'!AG$7,'Rooms Walls and Glass'!$D$1:$AB$1,0))=0,"",INDEX('Rooms Walls and Glass'!$D$3:$AB$17, MATCH($D10,'Rooms Walls and Glass'!$A$3:$A$17,0), MATCH('Unit 1 a'!AG$7,'Rooms Walls and Glass'!$D$1:$AB$1,0)))) | AH10: =IF(AG10="","-",AG10*$G10) -> - | AI10: =IF(AI$7="","",IF(INDEX('Rooms Walls and Glass'!$D$3:$AB$17, MATCH($D10,'Rooms Walls and Glass'!$A$3:$A$17,0), MATCH('Unit 1 a'!AI$7,'Rooms Walls and Glass'!$D$1:$AB$1,0))=0,"",INDEX('Rooms Walls and Glass'!$D$3:$AB$17, MATCH($D10,'Rooms Walls and Glass'!$A$3:$A$17,0), MATCH('Unit 1 a'!AI$7,'Rooms Walls and Glass'!$D$1:$AB$1,0)))) | AJ10: =IF(AI10="","-",AI10*$G10) -> - | AK10: =IF(AK$7="","",IF(INDEX('Rooms Walls and Glass'!$D$3:$AB$17, MATCH($D10,'Rooms Walls and Glass'!$A$3:$A$17,0), MATCH('Unit 1 a'!AK$7,'Rooms Walls and Glass'!$D$1:$AB$1,0))=0,"",INDEX('Rooms Walls and Glass'!$D$3:$AB$17, MATCH($D10,'Rooms Walls and Glass'!$A$3:$A$17,0), MATCH('Unit 1 a'!AK$7,'Rooms Walls and Glass'!$D$1:$AB$1,0)))) | AL10: =IF(AK10="","-",AK10*$G10) -> - | AM10: =IF(AM$7="","",IF(INDEX('Rooms Walls and Glass'!$D$3:$AB$17, MATCH($D10,'Rooms Walls and Glass'!$A$3:$A$17,0), MATCH('Unit 1 a'!AM$7,'Rooms Walls and Glass'!$D$1:$AB$1,0))=0,"",INDEX('Rooms Walls and Glass'!$D$3:$AB$17, MATCH($D10,'Rooms Walls and Glass'!$A$3:$A$17,0), MATCH('Unit 1 a'!AM$7,'Rooms Walls and Glass'!$D$1:$AB$1,0)))) | AN10: =IF(AM10="","-",AM10*$G10) -> - | AO10: =IF(AO$7="","",IF(INDEX('Rooms Walls and Glass'!$D$3:$AB$17, MATCH($D10,'Rooms Walls and Glass'!$A$3:$A$17,0), MATCH('Unit 1 a'!AO$7,'Rooms Walls and Glass'!$D$1:$AB$1,0))=0,"",INDEX('Rooms Walls and Glass'!$D$3:$AB$17, MATCH($D10,'Rooms Walls and Glass'!$A$3:$A$17,0), MATCH('Unit 1 a'!AO$7,'Rooms Walls and Glass'!$D$1:$AB$1,0)))) | AP10: =IF(AO10="","-",AO10*$G10) -> -
C11: G1 | D11: ='Rooms Walls and Glass'!A10 -> NorthEast | E11: Front | F11: (S) | G11: =INDEX('Glass CLF Calculation'!$A$4:$G$11,MATCH('Unit 1 a'!D11,'Glass CLF Calculation'!$A$4:$A$11,0),7) -> 7.8267093 | H11: Btu/hr-sf | I11: =SUM(K11,M11,O11,Q11,U11,W11,Y11,AA11,AC11,AE11,AG11,AI11,S11,AK11,AM11,AO11) -> 46 | J11: =IF(I11="","-",I11*$G11) -> 360.02863 | K11: =IF(K$7="","",IF(INDEX('Rooms Walls and Glass'!$D$3:$AB$17, MATCH($D11,'Rooms Walls and Glass'!$A$3:$A$17,0), MATCH('Unit 1 a'!K$7,'Rooms Walls and Glass'!$D$1:$AB$1,0))=0,"",INDEX('Rooms Walls and Glass'!$D$3:$AB$17, MATCH($D11,'Rooms Walls and Glass'!$A$3:$A$17,0), MATCH('Unit 1 a'!K$7,'Rooms Walls and Glass'!$D$1:$AB$1,0)))) -> 8 | L11: =IF(K11="","-",K11*$G11) -> 62.613675 | M11: =IF(M$7="","",IF(INDEX('Rooms Walls and Glass'!$D$3:$AB$17, MATCH($D11,'Rooms Walls and Glass'!$A$3:$A$17,0), MATCH('Unit 1 a'!M$7,'Rooms Walls and Glass'!$D$1:$AB$1,0))=0,"",INDEX('Rooms Walls and Glass'!$D$3:$AB$17, MATCH($D11,'Rooms Walls and Glass'!$A$3:$A$17,0), MATCH('Unit 1 a'!M$7,'Rooms Walls and Glass'!$D$1:$AB$1,0)))) | N11: =IF(M11="","-",M11*$G11) -> - | O11: =IF(O$7="","",IF(INDEX('Rooms Walls and Glass'!$D$3:$AB$17, MATCH($D11,'Rooms Walls and Glass'!$A$3:$A$17,0), MATCH('Unit 1 a'!O$7,'Rooms Walls and Glass'!$D$1:$AB$1,0))=0,"",INDEX('Rooms Walls and Glass'!$D$3:$AB$17, MATCH($D11,'Rooms Walls and Glass'!$A$3:$A$17,0), MATCH('Unit 1 a'!O$7,'Rooms Walls and Glass'!$D$1:$AB$1,0)))) -> 38 | P11: =IF(O11="","-",O11*$G11) -> 297.41495 | Q11: =IF(Q$7="","",IF(INDEX('Rooms Walls and Glass'!$D$3:$AB$17, MATCH($D11,'Rooms Walls and Glass'!$A$3:$A$17,0), MATCH('Unit 1 a'!Q$7,'Rooms Walls and Glass'!$D$1:$AB$1,0))=0,"",INDEX('Rooms Walls and Glass'!$D$3:$AB$17, MATCH($D11,'Rooms Walls and Glass'!$A$3:$A$17,0), MATCH('Unit 1 a'!Q$7,'Rooms Walls and Glass'!$D$1:$AB$1,0)))) | R11: =IF(Q11="","-",Q11*$G11) -> - | S11: =IF(S$7="","",IF(INDEX('Rooms Walls and Glass'!$D$3:$AB$17, MATCH($D11,'Rooms Walls and Glass'!$A$3:$A$17,0), MATCH('Unit 1 a'!S$7,'Rooms Walls and Glass'!$D$1:$AB$1,0))=0,"",INDEX('Rooms Walls and Glass'!$D$3:$AB$17, MATCH($D11,'Rooms Walls and Glass'!$A$3:$A$17,0), MATCH('Unit 1 a'!S$7,'Rooms Walls and Glass'!$D$1:$AB$1,0)))) | T11: =IF(S11="","-",S11*$G11) -> - | U11: =IF(U$7="","",IF(INDEX('Rooms Walls and Glass'!$D$3:$AB$17, MATCH($D11,'Rooms Walls and Glass'!$A$3:$A$17,0), MATCH('Unit 1 a'!U$7,'Rooms Walls and Glass'!$D$1:$AB$1,0))=0,"",INDEX('Rooms Walls and Glass'!$D$3:$AB$17, MATCH($D11,'Rooms Walls and Glass'!$A$3:$A$17,0), MATCH('Unit 1 a'!U$7,'Rooms Walls and Glass'!$D$1:$AB$1,0)))) | V11: =IF(U11="","-",U11*$G11) -> - | W11: =IF(W$7="","",IF(INDEX('Rooms Walls and Glass'!$D$3:$AB$17, MATCH($D11,'Rooms Walls and Glass'!$A$3:$A$17,0), MATCH('Unit 1 a'!W$7,'Rooms Walls and Glass'!$D$1:$AB$1,0))=0,"",INDEX('Rooms Walls and Glass'!$D$3:$AB$17, MATCH($D11,'Rooms Walls and Glass'!$A$3:$A$17,0), MATCH('Unit 1 a'!W$7,'Rooms Walls and Glass'!$D$1:$AB$1,0)))) | X11: =IF(W11="","-",W11*$G11) -> - | Y11: =IF(Y$7="","",IF(INDEX('Rooms Walls and Glass'!$D$3:$AB$17, MATCH($D11,'Rooms Walls and Glass'!$A$3:$A$17,0), MATCH('Unit 1 a'!Y$7,'Rooms Walls and Glass'!$D$1:$AB$1,0))=0,"",INDEX('Rooms Walls and Glass'!$D$3:$AB$17, MATCH($D11,'Rooms Walls and Glass'!$A$3:$A$17,0), MATCH('Unit 1 a'!Y$7,'Rooms Walls and Glass'!$D$1:$AB$1,0)))) | Z11: =IF(Y11="","-",Y11*$G11) -> - | AA11: =IF(AA$7="","",IF(INDEX('Rooms Walls and Glass'!$D$3:$AB$17, MATCH($D11,'Rooms Walls and Glass'!$A$3:$A$17,0), MATCH('Unit 1 a'!AA$7,'Rooms Walls and Glass'!$D$1:$AB$1,0))=0,"",INDEX('Rooms Walls and Glass'!$D$3:$AB$17, MATCH($D11,'Rooms Walls and Glass'!$A$3:$A$17,0), MATCH('Unit 1 a'!AA$7,'Rooms Walls and Glass'!$D$1:$AB$1,0)))) | AB11: =IF(AA11="","-",AA11*$G11) -> - | AC11: =IF(AC$7="","",IF(INDEX('Rooms Walls and Glass'!$D$3:$AB$17, MATCH($D11,'Rooms Walls and Glass'!$A$3:$A$17,0), MATCH('Unit 1 a'!AC$7,'Rooms Walls and Glass'!$D$1:$AB$1,0))=0,"",INDEX('Rooms Walls and Glass'!$D$3:$AB$17, MATCH($D11,'Rooms Walls and Glass'!$A$3:$A$17,0), MATCH('Unit 1 a'!AC$7,'Rooms Walls and Glass'!$D$1:$AB$1,0)))) | AD11: =IF(AC11="","-",AC11*$G11) -> - | AE11: =IF(AE$7="","",IF(INDEX('Rooms Walls and Glass'!$D$3:$AB$17, MATCH($D11,'Rooms Walls and Glass'!$A$3:$A$17,0), MATCH('Unit 1 a'!AE$7,'Rooms Walls and Glass'!$D$1:$AB$1,0))=0,"",INDEX('Rooms Walls and Glass'!$D$3:$AB$17, MATCH($D11,'Rooms Walls and Glass'!$A$3:$A$17,0), MATCH('Unit 1 a'!AE$7,'Rooms Walls and Glass'!$D$1:$AB$1,0)))) | AF11: =IF(AE11="","-",AE11*$G11) -> - | AG11: =IF(AG$7="","",IF(INDEX('Rooms Walls and Glass'!$D$3:$AB$17, MATCH($D11,'Rooms Walls and Glass'!$A$3:$A$17,0), MATCH('Unit 1 a'!AG$7,'Rooms Walls and Glass'!$D$1:$AB$1,0))=0,"",INDEX('Rooms Walls and Glass'!$D$3:$AB$17, MATCH($D11,'Rooms Walls and Glass'!$A$3:$A$17,0), MATCH('Unit 1 a'!AG$7,'Rooms Walls and Glass'!$D$1:$AB$1,0)))) | AH11: =IF(AG11="","-",AG11*$G11) -> - | AI11: =IF(AI$7="","",IF(INDEX('Rooms Walls and Glass'!$D$3:$AB$17, MATCH($D11,'Rooms Walls and Glass'!$A$3:$A$17,0), MATCH('Unit 1 a'!AI$7,'Rooms Walls and Glass'!$D$1:$AB$1,0))=0,"",INDEX('Rooms Walls and Glass'!$D$3:$AB$17, MATCH($D11,'Rooms Walls and Glass'!$A$3:$A$17,0), MATCH('Unit 1 a'!AI$7,'Rooms Walls and Glass'!$D$1:$AB$1,0)))) | AJ11: =IF(AI11="","-",AI11*$G11) -> - | AK11: =IF(AK$7="","",IF(INDEX('Rooms Walls and Glass'!$D$3:$AB$17, MATCH($D11,'Rooms Walls and Glass'!$A$3:$A$17,0), MATCH('Unit 1 a'!AK$7,'Rooms Walls and Glass'!$D$1:$AB$1,0))=0,"",INDEX('Rooms Walls and Glass'!$D$3:$AB$17, MATCH($D11,'Rooms Walls and Glass'!$A$3:$A$17,0), MATCH('Unit 1 a'!AK$7,'Rooms Walls and Glass'!$D$1:$AB$1,0)))) | AL11: =IF(AK11="","-",AK11*$G11) -> - | AM11: =IF(AM$7="","",IF(INDEX('Rooms Walls and Glass'!$D$3:$AB$17, MATCH($D11,'Rooms Walls and Glass'!$A$3:$A$17,0), MATCH('Unit 1 a'!AM$7,'Rooms Walls and Glass'!$D$1:$AB$1,0))=0,"",INDEX('Rooms Walls and Glass'!$D$3:$AB$17, MATCH($D11,'Rooms Walls and Glass'!$A$3:$A$17,0), MATCH('Unit 1 a'!AM$7,'Rooms Walls and Glass'!$D$1:$AB$1,0)))) | AN11: =IF(AM11="","-",AM11*$G11) -> - | AO11: =IF(AO$7="","",IF(INDEX('Rooms Walls and Glass'!$D$3:$AB$17, MATCH($D11,'Rooms Walls and Glass'!$A$3:$A$17,0), MATCH('Unit 1 a'!AO$7,'Rooms Walls and Glass'!$D$1:$AB$1,0))=0,"",INDEX('Rooms Walls and Glass'!$D$3:$AB$17, MATCH($D11,'Rooms Walls and Glass'!$A$3:$A$17,0), MATCH('Unit 1 a'!AO$7,'Rooms Walls and Glass'!$D$1:$AB$1,0)))) | AP11: =IF(AO11="","-",AO11*$G11) -> -
C12: G1 | D12: ='Rooms Walls and Glass'!A11 -> East | F12: (SW) | G12: =INDEX('Glass CLF Calculation'!$A$4:$G$11,MATCH('Unit 1 a'!D12,'Glass CLF Calculation'!$A$4:$A$11,0),7) -> 12.954 | H12: Btu/hr-sf | I12: =SUM(K12,M12,O12,Q12,U12,W12,Y12,AA12,AC12,AE12,AG12,AI12,S12,AK12,AM12,AO12) -> 0 | J12: =IF(I12="","-",I12*$G12) -> 0 | K12: =IF(K$7="","",IF(INDEX('Rooms Walls and Glass'!$D$3:$AB$17, MATCH($D12,'Rooms Walls and Glass'!$A$3:$A$17,0), MATCH('Unit 1 a'!K$7,'Rooms Walls and Glass'!$D$1:$AB$1,0))=0,"",INDEX('Rooms Walls and Glass'!$D$3:$AB$17, MATCH($D12,'Rooms Walls and Glass'!$A$3:$A$17,0), MATCH('Unit 1 a'!K$7,'Rooms Walls and Glass'!$D$1:$AB$1,0)))) | L12: =IF(K12="","-",K12*$G12) -> - | M12: =IF(M$7="","",IF(INDEX('Rooms Walls and Glass'!$D$3:$AB$17, MATCH($D12,'Rooms Walls and Glass'!$A$3:$A$17,0), MATCH('Unit 1 a'!M$7,'Rooms Walls and Glass'!$D$1:$AB$1,0))=0,"",INDEX('Rooms Walls and Glass'!$D$3:$AB$17, MATCH($D12,'Rooms Walls and Glass'!$A$3:$A$17,0), MATCH('Unit 1 a'!M$7,'Rooms Walls and Glass'!$D$1:$AB$1,0)))) | N12: =IF(M12="","-",M12*$G12) -> - | O12: =IF(O$7="","",IF(INDEX('Rooms Walls and Glass'!$D$3:$AB$17, MATCH($D12,'Rooms Walls and Glass'!$A$3:$A$17,0), MATCH('Unit 1 a'!O$7,'Rooms Walls and Glass'!$D$1:$AB$1,0))=0,"",INDEX('Rooms Walls and Glass'!$D$3:$AB$17, MATCH($D12,'Rooms Walls and Glass'!$A$3:$A$17,0), MATCH('Unit 1 a'!O$7,'Rooms Walls and Glass'!$D$1:$AB$1,0)))) | P12: =IF(O12="","-",O12*$G12) -> - | Q12: =IF(Q$7="","",IF(INDEX('Rooms Walls and Glass'!$D$3:$AB$17, MATCH($D12,'Rooms Walls and Glass'!$A$3:$A$17,0), MATCH('Unit 1 a'!Q$7,'Rooms Walls and Glass'!$D$1:$AB$1,0))=0,"",INDEX('Rooms Walls and Glass'!$D$3:$AB$17, MATCH($D12,'Rooms Walls and Glass'!$A$3:$A$17,0), MATCH('Unit 1 a'!Q$7,'Rooms Walls and Glass'!$D$1:$AB$1,0)))) | R12: =IF(Q12="","-",Q12*$G12) -> - | S12: =IF(S$7="","",IF(INDEX('Rooms Walls and Glass'!$D$3:$AB$17, MATCH($D12,'Rooms Walls and Glass'!$A$3:$A$17,0), MATCH('Unit 1 a'!S$7,'Rooms Walls and Glass'!$D$1:$AB$1,0))=0,"",INDEX('Rooms Walls and Glass'!$D$3:$AB$17, MATCH($D12,'Rooms Walls and Glass'!$A$3:$A$17,0), MATCH('Unit 1 a'!S$7,'Rooms Walls and Glass'!$D$1:$AB$1,0)))) | T12: =IF(S12="","-",S12*$G12) -> - | U12: =IF(U$7="","",IF(INDEX('Rooms Walls and Glass'!$D$3:$AB$17, MATCH($D12,'Rooms Walls and Glass'!$A$3:$A$17,0), MATCH('Unit 1 a'!U$7,'Rooms Walls and Glass'!$D$1:$AB$1,0))=0,"",INDEX('Rooms Walls and Glass'!$D$3:$AB$17, MATCH($D12,'Rooms Walls and Glass'!$A$3:$A$17,0), MATCH('Unit 1 a'!U$7,'Rooms Walls and Glass'!$D$1:$AB$1,0)))) | V12: =IF(U12="","-",U12*$G12) -> - | W12: =IF(W$7="","",IF(INDEX('Rooms Walls and Glass'!$D$3:$AB$17, MATCH($D12,'Rooms Walls and Glass'!$A$3:$A$17,0), MATCH('Unit 1 a'!W$7,'Rooms Walls and Glass'!$D$1:$AB$1,0))=0,"",INDEX('Rooms Walls and Glass'!$D$3:$AB$17, MATCH($D12,'Rooms Walls and Glass'!$A$3:$A$17,0), MATCH('Unit 1 a'!W$7,'Rooms Walls and Glass'!$D$1:$AB$1,0)))) | X12: =IF(W12="","-",W12*$G12) -> - | Y12: =IF(Y$7="","",IF(INDEX('Rooms Walls and Glass'!$D$3:$AB$17, MATCH($D12,'Rooms Walls and Glass'!$A$3:$A$17,0), MATCH('Unit 1 a'!Y$7,'Rooms Walls and Glass'!$D$1:$AB$1,0))=0,"",INDEX('Rooms Walls and Glass'!$D$3:$AB$17, MATCH($D12,'Rooms Walls and Glass'!$A$3:$A$17,0), MATCH('Unit 1 a'!Y$7,'Rooms Walls and Glass'!$D$1:$AB$1,0)))) | Z12: =IF(Y12="","-",Y12*$G12) -> - | AA12: =IF(AA$7="","",IF(INDEX('Rooms Walls and Glass'!$D$3:$AB$17, MATCH($D12,'Rooms Walls and Glass'!$A$3:$A$17,0), MATCH('Unit 1 a'!AA$7,'Rooms Walls and Glass'!$D$1:$AB$1,0))=0,"",INDEX('Rooms Walls and Glass'!$D$3:$AB$17, MATCH($D12,'Rooms Walls and Glass'!$A$3:$A$17,0), MATCH('Unit 1 a'!AA$7,'Rooms Walls and Glass'!$D$1:$AB$1,0)))) | AB12: =IF(AA12="","-",AA12*$G12) -> - | AC12: =IF(AC$7="","",IF(INDEX('Rooms Walls and Glass'!$D$3:$AB$17, MATCH($D12,'Rooms Walls and Glass'!$A$3:$A$17,0), MATCH('Unit 1 a'!AC$7,'Rooms Walls and Glass'!$D$1:$AB$1,0))=0,"",INDEX('Rooms Walls and Glass'!$D$3:$AB$17, MATCH($D12,'Rooms Walls and Glass'!$A$3:$A$17,0), MATCH('Unit 1 a'!AC$7,'Rooms Walls and Glass'!$D$1:$AB$1,0)))) | AD12: =IF(AC12="","-",AC12*$G12) -> - | AE12: =IF(AE$7="","",IF(INDEX('Rooms Walls and Glass'!$D$3:$AB$17, MATCH($D12,'Rooms Walls and Glass'!$A$3:$A$17,0), MATCH('Unit 1 a'!AE$7,'Rooms Walls and Glass'!$D$1:$AB$1,0))=0,"",INDEX('Rooms Walls and Glass'!$D$3:$AB$17, MATCH($D12,'Rooms Walls and Glass'!$A$3:$A$17,0), MATCH('Unit 1 a'!AE$7,'Rooms Walls and Glass'!$D$1:$AB$1,0)))) | AF12: =IF(AE12="","-",AE12*$G12) -> - | AG12: =IF(AG$7="","",IF(INDEX('Rooms Walls and Glass'!$D$3:$AB$17, MATCH($D12,'Rooms Walls and Glass'!$A$3:$A$17,0), MATCH('Unit 1 a'!AG$7,'Rooms Walls and Glass'!$D$1:$AB$1,0))=0,"",INDEX('Rooms Walls and Glass'!$D$3:$AB$17, MATCH($D12,'Rooms Walls and Glass'!$A$3:$A$17,0), MATCH('Unit 1 a'!AG$7,'Rooms Walls and Glass'!$D$1:$AB$1,0)))) | AH12: =IF(AG12="","-",AG12*$G12) -> - | AI12: =IF(AI$7="","",IF(INDEX('Rooms Walls and Glass'!$D$3:$AB$17, MATCH($D12,'Rooms Walls and Glass'!$A$3:$A$17,0), MATCH('Unit 1 a'!AI$7,'Rooms Walls and Glass'!$D$1:$AB$1,0))=0,"",INDEX('Rooms Walls and Glass'!$D$3:$AB$17, MATCH($D12,'Rooms Walls and Glass'!$A$3:$A$17,0), MATCH('Unit 1 a'!AI$7,'Rooms Walls and Glass'!$D$1:$AB$1,0)))) | AJ12: =IF(AI12="","-",AI12*$G12) -> - | AK12: =IF(AK$7="","",IF(INDEX('Rooms Walls and Glass'!$D$3:$AB$17, MATCH($D12,'Rooms Walls and Glass'!$A$3:$A$17,0), MATCH('Unit 1 a'!AK$7,'Rooms Walls and Glass'!$D$1:$AB$1,0))=0,"",INDEX('Rooms Walls and Glass'!$D$3:$AB$17, MATCH($D12,'Rooms Walls and Glass'!$A$3:$A$17,0), MATCH('Unit 1 a'!AK$7,'Rooms Walls and Glass'!$D$1:$AB$1,0)))) | AL12: =IF(AK12="","-",AK12*$G12) -> - | AM12: =IF(AM$7="","",IF(INDEX('Rooms Walls and Glass'!$D$3:$AB$17, MATCH($D12,'Rooms Walls and Glass'!$A$3:$A$17,0), MATCH('Unit 1 a'!AM$7,'Rooms Walls and Glass'!$D$1:$AB$1,0))=0,"",INDEX('Rooms Walls and Glass'!$D$3:$AB$17, MATCH($D12,'Rooms Walls and Glass'!$A$3:$A$17,0), MATCH('Unit 1 a'!AM$7,'Rooms Walls and Glass'!$D$1:$AB$1,0)))) | AN12: =IF(AM12="","-",AM12*$G12) -> - | AO12: =IF(AO$7="","",IF(INDEX('Rooms Walls and Glass'!$D$3:$AB$17, MATCH($D12,'Rooms Walls and Glass'!$A$3:$A$17,0), MATCH('Unit 1 a'!AO$7,'Rooms Walls and Glass'!$D$1:$AB$1,0))=0,"",INDEX('Rooms Walls and Glass'!$D$3:$AB$17, MATCH($D12,'Rooms Walls and Glass'!$A$3:$A$17,0), MATCH('Unit 1 a'!AO$7,'Rooms Walls and Glass'!$D$1:$AB$1,0)))) | AP12: =IF(AO12="","-",AO12*$G12) -> -
C13: G1 | D13: ='Rooms Walls and Glass'!A12 -> SouthEast | E13: Left | F13: (W) | G13: =INDEX('Glass CLF Calculation'!$A$4:$G$11,MATCH('Unit 1 a'!D13,'Glass CLF Calculation'!$A$4:$A$11,0),7) -> 14.271164 | H13: Btu/hr-sf | I13: =SUM(K13,M13,O13,Q13,U13,W13,Y13,AA13,AC13,AE13,AG13,AI13,S13,AK13,AM13,AO13) -> 16 | J13: =IF(I13="","-",I13*$G13) -> 228.33863 | K13: =IF(K$7="","",IF(INDEX('Rooms Walls and Glass'!$D$3:$AB$17, MATCH($D13,'Rooms Walls and Glass'!$A$3:$A$17,0), MATCH('Unit 1 a'!K$7,'Rooms Walls and Glass'!$D$1:$AB$1,0))=0,"",INDEX('Rooms Walls and Glass'!$D$3:$AB$17, MATCH($D13,'Rooms Walls and Glass'!$A$3:$A$17,0), MATCH('Unit 1 a'!K$7,'Rooms Walls and Glass'!$D$1:$AB$1,0)))) | L13: =IF(K13="","-",K13*$G13) -> - | M13: =IF(M$7="","",IF(INDEX('Rooms Walls and Glass'!$D$3:$AB$17, MATCH($D13,'Rooms Walls and Glass'!$A$3:$A$17,0), MATCH('Unit 1 a'!M$7,'Rooms Walls and Glass'!$D$1:$AB$1,0))=0,"",INDEX('Rooms Walls and Glass'!$D$3:$AB$17, MATCH($D13,'Rooms Walls and Glass'!$A$3:$A$17,0), MATCH('Unit 1 a'!M$7,'Rooms Walls and Glass'!$D$1:$AB$1,0)))) | N13: =IF(M13="","-",M13*$G13) -> - | O13: =IF(O$7="","",IF(INDEX('Rooms Walls and Glass'!$D$3:$AB$17, MATCH($D13,'Rooms Walls and Glass'!$A$3:$A$17,0), MATCH('Unit 1 a'!O$7,'Rooms Walls and Glass'!$D$1:$AB$1,0))=0,"",INDEX('Rooms Walls and Glass'!$D$3:$AB$17, MATCH($D13,'Rooms Walls and Glass'!$A$3:$A$17,0), MATCH('Unit 1 a'!O$7,'Rooms Walls and Glass'!$D$1:$AB$1,0)))) | P13: =IF(O13="","-",O13*$G13) -> - | Q13: =IF(Q$7="","",IF(INDEX('Rooms Walls and Glass'!$D$3:$AB$17, MATCH($D13,'Rooms Walls and Glass'!$A$3:$A$17,0), MATCH('Unit 1 a'!Q$7,'Rooms Walls and Glass'!$D$1:$AB$1,0))=0,"",INDEX('Rooms Walls and Glass'!$D$3:$AB$17, MATCH($D13,'Rooms Walls and Glass'!$A$3:$A$17,0), MATCH('Unit 1 a'!Q$7,'Rooms Walls and Glass'!$D$1:$AB$1,0)))) -> 16 | R13: =IF(Q13="","-",Q13*$G13) -> 228.33863 | S13: =IF(S$7="","",IF(INDEX('Rooms Walls and Glass'!$D$3:$AB$17, MATCH($D13,'Rooms Walls and Glass'!$A$3:$A$17,0), MATCH('Unit 1 a'!S$7,'Rooms Walls and Glass'!$D$1:$AB$1,0))=0,"",INDEX('Rooms Walls and Glass'!$D$3:$AB$17, MATCH($D13,'Rooms Walls and Glass'!$A$3:$A$17,0), MATCH('Unit 1 a'!S$7,'Rooms Walls and Glass'!$D$1:$AB$1,0)))) | T13: =IF(S13="","-",S13*$G13) -> - | U13: =IF(U$7="","",IF(INDEX('Rooms Walls and Glass'!$D$3:$AB$17, MATCH($D13,'Rooms Walls and Glass'!$A$3:$A$17,0), MATCH('Unit 1 a'!U$7,'Rooms Walls and Glass'!$D$1:$AB$1,0))=0,"",INDEX('Rooms Walls and Glass'!$D$3:$AB$17, MATCH($D13,'Rooms Walls and Glass'!$A$3:$A$17,0), MATCH('Unit 1 a'!U$7,'Rooms Walls and Glass'!$D$1:$AB$1,0)))) | V13: =IF(U13="","-",U13*$G13) -> - | W13: =IF(W$7="","",IF(INDEX('Rooms Walls and Glass'!$D$3:$AB$17, MATCH($D13,'Rooms Walls and Glass'!$A$3:$A$17,0), MATCH('Unit 1 a'!W$7,'Rooms Walls and Glass'!$D$1:$AB$1,0))=0,"",INDEX('Rooms Walls and Glass'!$D$3:$AB$17, MATCH($D13,'Rooms Walls and Glass'!$A$3:$A$17,0), MATCH('Unit 1 a'!W$7,'Rooms Walls and Glass'!$D$1:$AB$1,0)))) | X13: =IF(W13="","-",W13*$G13) -> - | Y13: =IF(Y$7="","",IF(INDEX('Rooms Walls and Glass'!$D$3:$AB$17, MATCH($D13,'Rooms Walls and Glass'!$A$3:$A$17,0), MATCH('Unit 1 a'!Y$7,'Rooms Walls and Glass'!$D$1:$AB$1,0))=0,"",INDEX('Rooms Walls and Glass'!$D$3:$AB$17, MATCH($D13,'Rooms Walls and Glass'!$A$3:$A$17,0), MATCH('Unit 1 a'!Y$7,'Rooms Walls and Glass'!$D$1:$AB$1,0)))) | Z13: =IF(Y13="","-",Y13*$G13) -> - | AA13: =IF(AA$7="","",IF(INDEX('Rooms Walls and Glass'!$D$3:$AB$17, MATCH($D13,'Rooms Walls and Glass'!$A$3:$A$17,0), MATCH('Unit 1 a'!AA$7,'Rooms Walls and Glass'!$D$1:$AB$1,0))=0,"",INDEX('Rooms Walls and Glass'!$D$3:$AB$17, MATCH($D13,'Rooms Walls and Glass'!$A$3:$A$17,0), MATCH('Unit 1 a'!AA$7,'Rooms Walls and Glass'!$D$1:$AB$1,0)))) | AB13: =IF(AA13="","-",AA13*$G13) -> - | AC13: =IF(AC$7="","",IF(INDEX('Rooms Walls and Glass'!$D$3:$AB$17, MATCH($D13,'Rooms Walls and Glass'!$A$3:$A$17,0), MATCH('Unit 1 a'!AC$7,'Rooms Walls and Glass'!$D$1:$AB$1,0))=0,"",INDEX('Rooms Walls and Glass'!$D$3:$AB$17, MATCH($D13,'Rooms Walls and Glass'!$A$3:$A$17,0), MATCH('Unit 1 a'!AC$7,'Rooms Walls and Glass'!$D$1:$AB$1,0)))) | AD13: =IF(AC13="","-",AC13*$G13) -> - | AE13: =IF(AE$7="","",IF(INDEX('Rooms Walls and Glass'!$D$3:$AB$17, MATCH($D13,'Rooms Walls and Glass'!$A$3:$A$17,0), MATCH('Unit 1 a'!AE$7,'Rooms Walls and Glass'!$D$1:$AB$1,0))=0,"",INDEX('Rooms Walls and Glass'!$D$3:$AB$17, MATCH($D13,'Rooms Walls and Glass'!$A$3:$A$17,0), MATCH('Unit 1 a'!AE$7,'Rooms Walls and Glass'!$D$1:$AB$1,0)))) | AF13: =IF(AE13="","-",AE13*$G13) -> - | AG13: =IF(AG$7="","",IF(INDEX('Rooms Walls and Glass'!$D$3:$AB$17, MATCH($D13,'Rooms Walls and Glass'!$A$3:$A$17,0), MATCH('Unit 1 a'!AG$7,'Rooms Walls and Glass'!$D$1:$AB$1,0))=0,"",INDEX('Rooms Walls and Glass'!$D$3:$AB$17, MATCH($D13,'Rooms Walls and Glass'!$A$3:$A$17,0), MATCH('Unit 1 a'!AG$7,'Rooms Walls and Glass'!$D$1:$AB$1,0)))) | AH13: =IF(AG13="","-",AG13*$G13) -> - | AI13: =IF(AI$7="","",IF(INDEX('Rooms Walls and Glass'!$D$3:$AB$17, MATCH($D13,'Rooms Walls and Glass'!$A$3:$A$17,0), MATCH('Unit 1 a'!AI$7,'Rooms Walls and Glass'!$D$1:$AB$1,0))=0,"",INDEX('Rooms Walls and Glass'!$D$3:$AB$17, MATCH($D13,'Rooms Walls and Glass'!$A$3:$A$17,0), MATCH('Unit 1 a'!AI$7,'Rooms Walls and Glass'!$D$1:$AB$1,0)))) | AJ13: =IF(AI13="","-",AI13*$G13) -> - | AK13: =IF(AK$7="","",IF(INDEX('Rooms Walls and Glass'!$D$3:$AB$17, MATCH($D13,'Rooms Walls and Glass'!$A$3:$A$17,0), MATCH('Unit 1 a'!AK$7,'Rooms Walls and Glass'!$D$1:$AB$1,0))=0,"",INDEX('Rooms Walls and Glass'!$D$3:$AB$17, MATCH($D13,'Rooms Walls and Glass'!$A$3:$A$17,0), MATCH('Unit 1 a'!AK$7,'Rooms Walls and Glass'!$D$1:$AB$1,0)))) | AL13: =IF(AK13="","-",AK13*$G13) -> - | AM13: =IF(AM$7="","",IF(INDEX('Rooms Walls and Glass'!$D$3:$AB$17, MATCH($D13,'Rooms Walls and Glass'!$A$3:$A$17,0), MATCH('Unit 1 a'!AM$7,'Rooms Walls and Glass'!$D$1:$AB$1,0))=0,"",INDEX('Rooms Walls and Glass'!$D$3:$AB$17, MATCH($D13,'Rooms Walls and Glass'!$A$3:$A$17,0), MATCH('Unit 1 a'!AM$7,'Rooms Walls and Glass'!$D$1:$AB$1,0)))) | AN13: =IF(AM13="","-",AM13*$G13) -> - | AO13: =IF(AO$7="","",IF(INDEX('Rooms Walls and Glass'!$D$3:$AB$17, MATCH($D13,'Rooms Walls and Glass'!$A$3:$A$17,0), MATCH('Unit 1 a'!AO$7,'Rooms Walls and Glass'!$D$1:$AB$1,0))=0,"",INDEX('Rooms Walls and Glass'!$D$3:$AB$17, MATCH($D13,'Rooms Walls and Glass'!$A$3:$A$17,0), MATCH('Unit 1 a'!AO$7,'Rooms Walls and Glass'!$D$1:$AB$1,0)))) | AP13: =IF(AO13="","-",AO13*$G13) -> -
C14: G1 | D14: ='Rooms Walls and Glass'!A13 -> South | F14: (NW) | G14: =INDEX('Glass CLF Calculation'!$A$4:$G$11,MATCH('Unit 1 a'!D14,'Glass CLF Calculation'!$A$4:$A$11,0),7) -> 15.869088 | H14: Btu/hr-sf | I14: =SUM(K14,M14,O14,Q14,U14,W14,Y14,AA14,AC14,AE14,AG14,AI14,S14,AK14,AM14,AO14) -> 0 | J14: =IF(I14="","-",I14*$G14) -> 0 | K14: =IF(K$7="","",IF(INDEX('Rooms Walls and Glass'!$D$3:$AB$17, MATCH($D14,'Rooms Walls and Glass'!$A$3:$A$17,0), MATCH('Unit 1 a'!K$7,'Rooms Walls and Glass'!$D$1:$AB$1,0))=0,"",INDEX('Rooms Walls and Glass'!$D$3:$AB$17, MATCH($D14,'Rooms Walls and Glass'!$A$3:$A$17,0), MATCH('Unit 1 a'!K$7,'Rooms Walls and Glass'!$D$1:$AB$1,0)))) | L14: =IF(K14="","-",K14*$G14) -> - | M14: =IF(M$7="","",IF(INDEX('Rooms Walls and Glass'!$D$3:$AB$17, MATCH($D14,'Rooms Walls and Glass'!$A$3:$A$17,0), MATCH('Unit 1 a'!M$7,'Rooms Walls and Glass'!$D$1:$AB$1,0))=0,"",INDEX('Rooms Walls and Glass'!$D$3:$AB$17, MATCH($D14,'Rooms Walls and Glass'!$A$3:$A$17,0), MATCH('Unit 1 a'!M$7,'Rooms Walls and Glass'!$D$1:$AB$1,0)))) | N14: =IF(M14="","-",M14*$G14) -> - | O14: =IF(O$7="","",IF(INDEX('Rooms Walls and Glass'!$D$3:$AB$17, MATCH($D14,'Rooms Walls and Glass'!$A$3:$A$17,0), MATCH('Unit 1 a'!O$7,'Rooms Walls and Glass'!$D$1:$AB$1,0))=0,"",INDEX('Rooms Walls and Glass'!$D$3:$AB$17, MATCH($D14,'Rooms Walls and Glass'!$A$3:$A$17,0), MATCH('Unit 1 a'!O$7,'Rooms Walls and Glass'!$D$1:$AB$1,0)))) | P14: =IF(O14="","-",O14*$G14) -> - | Q14: =IF(Q$7="","",IF(INDEX('Rooms Walls and Glass'!$D$3:$AB$17, MATCH($D14,'Rooms Walls and Glass'!$A$3:$A$17,0), MATCH('Unit 1 a'!Q$7,'Rooms Walls and Glass'!$D$1:$AB$1,0))=0,"",INDEX('Rooms Walls and Glass'!$D$3:$AB$17, MATCH($D14,'Rooms Walls and Glass'!$A$3:$A$17,0), MATCH('Unit 1 a'!Q$7,'Rooms Walls and Glass'!$D$1:$AB$1,0)))) | R14: =IF(Q14="","-",Q14*$G14) -> - | S14: =IF(S$7="","",IF(INDEX('Rooms Walls and Glass'!$D$3:$AB$17, MATCH($D14,'Rooms Walls and Glass'!$A$3:$A$17,0), MATCH('Unit 1 a'!S$7,'Rooms Walls and Glass'!$D$1:$AB$1,0))=0,"",INDEX('Rooms Walls and Glass'!$D$3:$AB$17, MATCH($D14,'Rooms Walls and Glass'!$A$3:$A$17,0), MATCH('Unit 1 a'!S$7,'Rooms Walls and Glass'!$D$1:$AB$1,0)))) | T14: =IF(S14="","-",S14*$G14) -> - | U14: =IF(U$7="","",IF(INDEX('Rooms Walls and Glass'!$D$3:$AB$17, MATCH($D14,'Rooms Walls and Glass'!$A$3:$A$17,0), MATCH('Unit 1 a'!U$7,'Rooms Walls and Glass'!$D$1:$AB$1,0))=0,"",INDEX('Rooms Walls and Glass'!$D$3:$AB$17, MATCH($D14,'Rooms Walls and Glass'!$A$3:$A$17,0), MATCH('Unit 1 a'!U$7,'Rooms Walls and Glass'!$D$1:$AB$1,0)))) | V14: =IF(U14="","-",U14*$G14) -> - | W14: =IF(W$7="","",IF(INDEX('Rooms Walls and Glass'!$D$3:$AB$17, MATCH($D14,'Rooms Walls and Glass'!$A$3:$A$17,0), MATCH('Unit 1 a'!W$7,'Rooms Walls and Glass'!$D$1:$AB$1,0))=0,"",INDEX('Rooms Walls and Glass'!$D$3:$AB$17, MATCH($D14,'Rooms Walls and Glass'!$A$3:$A$17,0), MATCH('Unit 1 a'!W$7,'Rooms Walls and Glass'!$D$1:$AB$1,0)))) | X14: =IF(W14="","-",W14*$G14) -> - | Y14: =IF(Y$7="","",IF(INDEX('Rooms Walls and Glass'!$D$3:$AB$17, MATCH($D14,'Rooms Walls and Glass'!$A$3:$A$17,0), MATCH('Unit 1 a'!Y$7,'Rooms Walls and Glass'!$D$1:$AB$1,0))=0,"",INDEX('Rooms Walls and Glass'!$D$3:$AB$17, MATCH($D14,'Rooms Walls and Glass'!$A$3:$A$17,0), MATCH('Unit 1 a'!Y$7,'Rooms Walls and Glass'!$D$1:$AB$1,0)))) | Z14: =IF(Y14="","-",Y14*$G14) -> - | AA14: =IF(AA$7="","",IF(INDEX('Rooms Walls and Glass'!$D$3:$AB$17, MATCH($D14,'Rooms Walls and Glass'!$A$3:$A$17,0), MATCH('Unit 1 a'!AA$7,'Rooms Walls and Glass'!$D$1:$AB$1,0))=0,"",INDEX('Rooms Walls and Glass'!$D$3:$AB$17, MATCH($D14,'Rooms Walls and Glass'!$A$3:$A$17,0), MATCH('Unit 1 a'!AA$7,'Rooms Walls and Glass'!$D$1:$AB$1,0)))) | AB14: =IF(AA14="","-",AA14*$G14) -> - | AC14: =IF(AC$7="","",IF(INDEX('Rooms Walls and Glass'!$D$3:$AB$17, MATCH($D14,'Rooms Walls and Glass'!$A$3:$A$17,0), MATCH('Unit 1 a'!AC$7,'Rooms Walls and Glass'!$D$1:$AB$1,0))=0,"",INDEX('Rooms Walls and Glass'!$D$3:$AB$17, MATCH($D14,'Rooms Walls and Glass'!$A$3:$A$17,0), MATCH('Unit 1 a'!AC$7,'Rooms Walls and Glass'!$D$1:$AB$1,0)))) | AD14: =IF(AC14="","-",AC14*$G14) -> - | AE14: =IF(AE$7="","",IF(INDEX('Rooms Walls and Glass'!$D$3:$AB$17, MATCH($D14,'Rooms Walls and Glass'!$A$3:$A$17,0), MATCH('Unit 1 a'!AE$7,'Rooms Walls and Glass'!$D$1:$AB$1,0))=0,"",INDEX('Rooms Walls and Glass'!$D$3:$AB$17, MATCH($D14,'Rooms Walls and Glass'!$A$3:$A$17,0), MATCH('Unit 1 a'!AE$7,'Rooms Walls and Glass'!$D$1:$AB$1,0)))) | AF14: =IF(AE14="","-",AE14*$G14) -> - | AG14: =IF(AG$7="","",IF(INDEX('Rooms Walls and Glass'!$D$3:$AB$17, MATCH($D14,'Rooms Walls and Glass'!$A$3:$A$17,0), MATCH('Unit 1 a'!AG$7,'Rooms Walls and Glass'!$D$1:$AB$1,0))=0,"",INDEX('Rooms Walls and Glass'!$D$3:$AB$17, MATCH($D14,'Rooms Walls and Glass'!$A$3:$A$17,0), MATCH('Unit 1 a'!AG$7,'Rooms Walls and Glass'!$D$1:$AB$1,0)))) | AH14: =IF(AG14="","-",AG14*$G14) -> - | AI14: =IF(AI$7="","",IF(INDEX('Rooms Walls and Glass'!$D$3:$AB$17, MATCH($D14,'Rooms Walls and Glass'!$A$3:$A$17,0), MATCH('Unit 1 a'!AI$7,'Rooms Walls and Glass'!$D$1:$AB$1,0))=0,"",INDEX('Rooms Walls and Glass'!$D$3:$AB$17, MATCH($D14,'Rooms Walls and Glass'!$A$3:$A$17,0), MATCH('Unit 1 a'!AI$7,'Rooms Walls and Glass'!$D$1:$AB$1,0)))) | AJ14: =IF(AI14="","-",AI14*$G14) -> - | AK14: =IF(AK$7="","",IF(INDEX('Rooms Walls and Glass'!$D$3:$AB$17, MATCH($D14,'Rooms Walls and Glass'!$A$3:$A$17,0), MATCH('Unit 1 a'!AK$7,'Rooms Walls and Glass'!$D$1:$AB$1,0))=0,"",INDEX('Rooms Walls and Glass'!$D$3:$AB$17, MATCH($D14,'Rooms Walls and Glass'!$A$3:$A$17,0), MATCH('Unit 1 a'!AK$7,'Rooms Walls and Glass'!$D$1:$AB$1,0)))) | AL14: =IF(AK14="","-",AK14*$G14) -> - | AM14: =IF(AM$7="","",IF(INDEX('Rooms Walls and Glass'!$D$3:$AB$17, MATCH($D14,'Rooms Walls and Glass'!$A$3:$A$17,0), MATCH('Unit 1 a'!AM$7,'Rooms Walls and Glass'!$D$1:$AB$1,0))=0,"",INDEX('Rooms Walls and Glass'!$D$3:$AB$17, MATCH($D14,'Rooms Walls and Glass'!$A$3:$A$17,0), MATCH('Unit 1 a'!AM$7,'Rooms Walls and Glass'!$D$1:$AB$1,0)))) | AN14: =IF(AM14="","-",AM14*$G14) -> - | AO14: =IF(AO$7="","",IF(INDEX('Rooms Walls and Glass'!$D$3:$AB$17, MATCH($D14,'Rooms Walls and Glass'!$A$3:$A$17,0), MATCH('Unit 1 a'!AO$7,'Rooms Walls and Glass'!$D$1:$AB$1,0))=0,"",INDEX('Rooms Walls and Glass'!$D$3:$AB$17, MATCH($D14,'Rooms Walls and Glass'!$A$3:$A$17,0), MATCH('Unit 1 a'!AO$7,'Rooms Walls and Glass'!$D$1:$AB$1,0)))) | AP14: =IF(AO14="","-",AO14*$G14) -> -
